<?xml version="1.0" encoding="utf-8"?>
<mujoco model="generated_environment">
  <option timestep="0.002" integrator="implicitfast" cone="elliptic" iterations="100" gravity="0 0 -9.81" />
  <default>
    <geom density="1" />
  </default>
  <asset>
    <texture builtin="gradient" height="3072" rgb1="0.3 0.5 0.7" rgb2="0 0 0" type="skybox" width="512" />
    <texture builtin="checker" height="300" mark="edge" markrgb="0.8 0.8 0.8" name="groundplane" rgb1="0.2 0.3 0.4" rgb2="0.1 0.2 0.3" type="2d" width="300" />
    <material name="groundplane" reflectance="0.2" texrepeat="5 5" texture="groundplane" texuniform="true" />
    <material name="robot" rgba="1.0 1.0 0.0 1.0" />
  </asset>
  <worldbody>
    <light dir="0 0 -1" directional="true" pos="0 0 1.5" />
    <geom condim="4" friction="0.5 0.005 0.001" material="groundplane" name="floor" size="0 0 0.05" type="plane" />
    <body name="walls">
      <geom name="wall_1" condim="4" pos="-1.165000 0.000000 0.080000" rgba="0.800000011920929 0.800000011920929 0.800000011920929 1.0" size="0.011650 1.165000 0.080000" type="box" />
      <geom name="wall_2" condim="4" pos="1.165000 0.000000 0.080000" rgba="0.800000011920929 0.800000011920929 0.800000011920929 1.0" size="0.011650 1.165000 0.080000" type="box" />
      <geom name="wall_3" condim="4" pos="0.000000 -1.165000 0.080000" rgba="0.800000011920929 0.800000011920929 0.800000011920929 1.0" size="1.165000 0.011650 0.080000" type="box" />
      <geom name="wall_4" condim="4" pos="0.000000 1.165000 0.080000" rgba="0.800000011920929 0.800000011920929 0.800000011920929 1.0" size="1.165000 0.011650 0.080000" type="box" />
      <geom name="wall_5" condim="4" pos="0.000000 0.699000 0.080000" rgba="0.800000011920929 0.800000011920929 0.800000011920929 1.0" size="0.011650 0.466000 0.080000" type="box" />
      <geom name="wall_6" condim="4" pos="-0.582500 0.000000 0.080000" rgba="0.800000011920929 0.800000011920929 0.800000011920929 1.0" size="0.582500 0.011650 0.080000" type="box" />
      <geom name="wall_7" condim="4" pos="0.000000 -0.699000 0.080000" rgba="0.800000011920929 0.800000011920929 0.800000011920929 1.0" size="0.011650 0.466000 0.080000" type="box" />
      <geom name="wall_8" condim="4" pos="0.466000 0.466000 0.080000" rgba="0.800000011920929 0.800000011920929 0.800000011920929 1.0" size="0.466000 0.011650 0.080000" type="box" />
    </body>
        <body name="car" pos="-0.143165 0.241594 0.010000">
      <freejoint name="car_freejoint"/>
      <inertial pos="0.000000 0 0.037500" mass="0.350000"
                diaginertia="0.000266 0.000266 0.000286"/>
      <geom name="front_chassis_collision" type="box"
            pos="0.017500 0 0.037500" size="0.017500 0.035000 0.032500"
            rgba="0.3 0.3 0.7 1"/>
      <geom name="rear_chassis_collision" type="box"
            pos="-0.017500 0 0.037500" size="0.017500 0.035000 0.032500"
            rgba="0.25 0.25 0.6 1"/>
      <geom name="front_marker" type="box"
            pos="0.034000 0 0.050500" size="0.002000 0.015000 0.010000"
            rgba="1.0 0.2 0.2 1" contype="0" conaffinity="0"/>
      <body name="rear_support_body" pos="-0.030000 0.000000 0.002500">
        <joint name="rear_caster_joint" type="ball" damping="0.0001"/>
        <inertial pos="0 0 0" mass="0.025000"
                  diaginertia="0.000001 0.000001 0.000001"/>
        <geom name="rear_support" type="sphere" pos="0 0 0" size="0.002500"
              friction="0.000000 0.000000 0.000000" rgba="0.7 0.1 0.1 1"/>
      </body>
      <body name="front_support_body" pos="0.030000 0.000000 0.002500">
        <joint name="front_caster_joint" type="ball" damping="0.0001"/>
        <inertial pos="0 0 0" mass="0.025000"
                  diaginertia="0.000001 0.000001 0.000001"/>
        <geom name="front_support" type="sphere" pos="0 0 0" size="0.002500"
              friction="0.000000 0.000000 0.000000" rgba="0.1 0.7 0.1 1"/>
      </body>
      <body name="left_wheel" pos="0.000000 0.037500 0.015000">
        <inertial pos="0 0 0" mass="0.050000"
                  diaginertia="0.000003 0.000006 0.000003"/>
        <joint name="left_wheel_joint" type="hinge" axis="0 1 0" damping="0.01" armature="0.0001"/>
        <geom name="left_wheel_collision" type="cylinder"
              size="0.015000 0.000500" euler="90 0 0" rgba="0.1 0.1 0.1 1"/>
      </body>
      <body name="right_wheel" pos="0.000000 -0.037500 0.015000">
        <inertial pos="0 0 0" mass="0.050000"
                  diaginertia="0.000003 0.000006 0.000003"/>
        <joint name="right_wheel_joint" type="hinge" axis="0 1 0" damping="0.01" armature="0.0001"/>
        <geom name="right_wheel_collision" type="cylinder"
              size="0.015000 0.000500" euler="90 0 0" rgba="0.1 0.1 0.1 1"/>
      </body>
    </body>
  </worldbody>
    <actuator>
    <velocity name="left_wheel_drive" joint="left_wheel_joint"
              ctrlrange="-25.000000 25.000000"
              kv="0.750000" forcerange="-0.500000 0.500000"/>
    <velocity name="right_wheel_drive" joint="right_wheel_joint"
              ctrlrange="-25.000000 25.000000"
              kv="0.750000" forcerange="-0.500000 0.500000"/>
  </actuator>
</mujoco>